Workbook
Name Lifestyle_upgrade_every_5y_Max: 'Lifestyle Strategy'!$M$6
Name Lifestyle_upgrade_every_5y_Min: 'Lifestyle Strategy'!$M$5
Name Lifestyle_upgrade_every_5y_Mostlikely: 'Lifestyle Strategy'!$M$7
Name Lifestyle_upgrade_every_5y_Triangular_Distribution: 'Lifestyle Strategy'!$M$4
Name Post_retirement_Lifestyle_Upgrade_every_5y_Max: 'Lifestyle Strategy'!$M$19
Name Post_retirement_Lifestyle_Upgrade_every_5y_Min: 'Lifestyle Strategy'!$M$18
Name Post_retirement_Lifestyle_Upgrade_every_5y_Mostlikely: 'Lifestyle Strategy'!$M$20

Sheet Pre-Retirement_cal
A1: Emily's Basic Information | D1: Employee Contribution | I1: Total Contribution | K1: Total Profit | M1: Corpus at Retirement | P1: Expected Corpus for Post Retirement | R1: Sustainable Post Retirement ? | U1: Key Feature Selected
A2: Salary | B2: 70000 | D2: Starting rate | E2: 0.03 | M2: Pre Ret. | N2: Post Ret. | O2: Total Corpus | BY2: Yes
A3: Hike Rise | B3: 0.035 | D3: Increase every year | E3: 2 | I3: =TEXT(($I$7)/1000000,"[$$-en-US]0.00")&"M" -> $0.89M | K3: =TEXT(($K$7)/1000000, "[$$-en-US]0.00") & "M" -> $3.95M | M3: =TEXT(($M$7)/1000000, "[$$-en-US]0.00") & "M" -> $4.84M | N3: =TEXT(($N$7)/1000000, "[$$-en-US]0.00") & "M" -> $2.12M | O3: =TEXT(($O$7)/1000000, "[$$-en-US]0.00") & "M" -> $6.94M | P3: =TEXT(($P$7)/1000000, "[$$-en-US]0.00") & "M" -> $4.18M | R3: =IF(O7>=P7, "Yes", "No") -> Yes | U3: Has_Partner_Contributed | V3: =IF($V$10 = $X$8, "Random",IF($V$10 =$U$8,"Yes","No")) -> Random | W3: Has_Double_Promotion | X3: =IF($V$10 = $X$8, "Random",IF($V$10 =$U$8,"Yes","No")) -> Random | Y3: Has_Partner | Z3: =IF($V$10 = $X$8, "Random",IF($V$10 =$U$8,"Yes","No")) -> Random | BY3: No
A4: Salary std. dev | B4: 0.007 | D4: Increase percentage | E4: =IF(X4="Random", IF(RANDBETWEEN(0,1)=1,0.01,0), IF(X4="Yes",0.01,0)) -> 0.01 | U4: Has_Children | V4: =IF($V$10=$X$8,"Random",IF($V$10=$W$8, "Yes","No")) -> Random | W4: Has_Increase_in_Contribution | X4: =IF($V$10 = $X$8, "Random",IF($V$10 =$U$8,"Yes","No")) -> Random | Y4: Has_Invested_Post_Retirement | Z4: =IF($V$10 = $X$8, "Random",IF($V$10 =$U$8,"Yes","No")) -> Random | BY4: Random
A5: Double Promotion Year | B5: =IF($B$7="No",0,RANDBETWEEN(5,30)) -> 10 | D5: Max rate | E5: 0.12 | U5: Has_Purchase_New_Home | V5: =IF($V$10=$X$8,"Random",IF($V$10=$W$8, "Yes","No")) -> Random | W5: Has_Lumpsum_Deposit | X5: =IF($V$10 = $X$8, "Random",IF($V$10 =$U$8,"Yes","No")) -> Random
A6: ACC Levy | B6: 0.0167 | D6: Lumpsum Every Year | E6: 5 | U6: Has_Unforeseen Withdrawal | V6: =IF($V$10=$X$8,"Random",IF($V$10=$W$8, "Yes","No")) -> Random | W6: Has_Lifestyle_Upgrade | X6: =IF($V$10=$X$8, "Random", IF( $V$10=W8, "Yes","No")) -> Random
A7: Double Promotion Year_Considered | B7: =IF(X3="Random",IF(RANDBETWEEN(0,1) = 0, "No", "Yes"),X3) -> Yes | D7: Lumpsum Amount | E7: =IF(X5="Random", IF(RANDBETWEEN(0,1)=1,10000,0), IF(X5="Yes",10000,0)) -> 10000 | I7: =SUM($Q$13:$Q$48) -> 890363.13 | K7: =$M$7-$I$7 -> 3951835.5 | M7: =BU51 -> 4842198.6 | N7: =BV51 -> 2119069.3 | O7: =BW51 -> 6936178 | P7: =BX51 -> 4175484.2
U8: Best Scenario | V8: Neutral Scenario | W8: Worst Scenario | X8: Random
A9: Pre Retirement Fund Calculation
U10: Selected Scenario | V10: Random
A12: Index | B12: Year | C12: Age | D12: Gross Salary | E12: Salary Hike Value | F12: Salary Hike % | G12: Income Tax | H12: ACC Levy | I12: Net Salary | J12: Employee Contribution Rate % | K12: Employer Contribution Rate % | L12: Partner Contribution | M12: Employee Contribution | N12: Employer Contribution | O12: Partner Contribution | P12: Lump Sum Added | Q12: Total Contribution | R12: Harboursafe Contribution | S12: Harboursafe Return | T12: Harbour safe return_value | U12: Harboursafe_corpus | V12: Horizon Contribution | W12: Horizon Return | X12: Horizon return value | Y12: Horizon Corpus | Z12: SkyHigh Contribution | AA12: SkyHigh Return | AB12: SkyHigh return value | AC12: SkyHigh corpus | AD12: Foreign_Equities Contribution | AE12: Foreign_Equities Return | AF12: Foreign return value | AG12: Bitcoin Contribution | AH12: Bitcoin Return | AI12: Bitcoin return value | AJ12: Bitcoin Corpus | AK12: FIF Tax (NZD) | AL12: FIF Tax % of Foreign Value | AM12: Foreign corpus | AN12: Foreign corpus after FIF tax | AO12: Rent | AP12: Groceries | AQ12: Travel | AR12: Utilities | AS12: Insurance | AT12: Leisure | AU12: Misc | AV12: Owns Home_EMI | AW12: Children Expense | AX12: Total Spent | AY12: Unforeseen Withdrawal | AZ12: Requested Withdrawal | BA12: Withdrawal Shortfall | BB12: Final Corpus Fund Value | BC12: Corpus Amount in Millions | BQ12: Post Retirement Fund Calculation
B13: 0 | C13: 30 | D13: =B2 -> 70000 | E13: 0 | F13: 0 | G13: ='Tax rate cal'!C10 -> 13220.5 | H13: =$B$6*D13 -> 1169 | I13: =D13-G13-H13 -> 55610.5 | J13: =MIN($E$2 + INT(B13/$E$3)*$E$4, $E$5) -> 0.03 | K13: 0.03 | L13: =IF(O13 = 0,0,'Lifestyle Strategy'!$Q$9) -> 0 | M13: =I13*J13 -> 1668.315 | N13: =I13*K13 -> 1668.315 | O13: =IF(AND('Lifestyle Strategy'!$Q$2="Yes", B13 >='Lifestyle Strategy'!$Q$3), I13 * 'Lifestyle Strategy'!$Q$9, 0 ) -> 0 | P13: =IF(B13<10,0,IF(MOD(B13, $E$6) = 0, $E$7, 0)) -> 0 | Q13: =M13+N13+O13+P13 -> 3336.63 | R13: =IF(B13<=5, Q13*'Fund Allocation Strategy'!$B$2, IF(B13<=10, Q13*'Fund Allocation Strategy'!$B$3, IF(B13<=15, Q13*'Fund Allocation Strategy'!$B$4, IF(B13<=20, Q13*'Fund Allocation Strategy'!$B$5, IF(B13<=25, Q13*'Fund Allocation Strategy'!$B$6, IF(B13<=30, Q13*'Fund Allocation Strategy'!$B$7, Q13*'Fund Allocation Strategy'!$B$8)))))) -> 166.8315 | S13: =_xlfn.NORM.INV(RAND(),'Fund Allocation Strategy'!$B$11,'Fund Allocation Strategy'!$C$11) -> 0.037283263 | T13: =R13*S13*0.5 -> 3.1100114 | U13: =R13+T13 -> 169.94151 | V13: =IF(B13<=5, Q13*'Fund Allocation Strategy'!$C$2, IF(B13<=10, Q13*'Fund Allocation Strategy'!$C$3, IF(B13<=15, Q13*'Fund Allocation Strategy'!$C$4, IF(B13<=20, Q13*'Fund Allocation Strategy'!$C$5, IF(B13<=25, Q13*'Fund Allocation Strategy'!$C$6, IF(B13<=30, Q13*'Fund Allocation Strategy'!$C$7, Q13*'Fund Allocation Strategy'!$C$8)))))) -> 166.8315 | W13: =_xlfn.NORM.INV(RAND(),'Fund Allocation Strategy'!$B$12,'Fund Allocation Strategy'!$C$12) -> 0.070556951 | X13: =V13*W13*0.5 -> 5.885561 | Y13: =V13+X13 -> 172.71706 | Z13: =IF(B13<=5, Q13*'Fund Allocation Strategy'!$D$2, IF(B13<=10, Q13*'Fund Allocation Strategy'!$D$3, IF(B13<=15, Q13*'Fund Allocation Strategy'!$D$4, IF(B13<=20, Q13*'Fund Allocation Strategy'!$D$5, IF(B13<=25, Q13*'Fund Allocation Strategy'!$D$6, IF(B13<=30, Q13*'Fund Allocation Strategy'!$D$7, Q13*'Fund Allocation Strategy'!$D$8)))))) -> 1501.4835 | AA13: =_xlfn.NORM.INV(RAND(),'Fund Allocation Strategy'!$B$13,'Fund Allocation Strategy'!$C$13) -> 0.10192759 | AB13: =Z13*AA13*0.5 -> 76.5213 | AC13: =Z13+AB13 -> 1578.0048 | AD13: =IF(B13<=5, Q13*'Fund Allocation Strategy'!$E$2, IF(B13<=10, Q13*'Fund Allocation Strategy'!$E$3, IF(B13<=15, Q13*'Fund Allocation Strategy'!$E$4, IF(B13<=20, Q13*'Fund Allocation Strategy'!$E$5, IF(B13<=25, Q13*'Fund Allocation Strategy'!$E$6, IF(B13<=30, Q13*'Fund Allocation Strategy'!$E$7, Q13*'Fund Allocation Strategy'!$E$8)))))) -> 1000.989 | AE13: =_xlfn.NORM.INV(RAND(), 'Fund Allocation Strategy'!$B$14, 'Fund Allocation Strategy'!$C$14) + _xlfn.NORM.INV(RAND(), 'Fund Allocation Strategy'!$D$14,'Fund Allocation Strategy'!$E$14) -> 0.11676117 | AF13: =AD13*AE13*0.5 -> 58.438323 | AG13: =IF(B13<=5, Q13*'Fund Allocation Strategy'!$F$2, IF(B13<=10, Q13*'Fund Allocation Strategy'!$F$3, IF(B13<=15, Q13*'Fund Allocation Strategy'!$F$4, IF(B13<=20, Q13*'Fund Allocation Strategy'!$F$5, IF(B13<=25, Q13*'Fund Allocation Strategy'!$F$6, IF(B13<=30, Q13*'Fund Allocation Strategy'!$F$7, Q13*'Fund Allocation Strategy'!$F$8)))))) -> 500.4945 | AH13: =_xlfn.NORM.INV(RAND(),'Fund Allocation Strategy'!$B$15,'Fund Allocation Strategy'!$C$15) -> 0.20108929 | AI13: =AG13*AH13*0.5 -> 50.322042 | AJ13: =AG13+AI13 -> 550.81654 | AK13: =IF(AM13<50000,0, AM13*0.015) -> 0 | AL13: =IF(AM13<50000,0,0.015) -> 0 | AM13: =AD13+AF13 -> 1059.4273 | AN13: =AM13-AK13 -> 1059.4273 | AO13: =IF(AV13 = 0, I13 * ( 'Lifestyle Strategy'!$B$2 + ('Lifestyle Strategy'!$C$2 - 'Lifestyle Strategy'!$B$2) * _xlfn.BETA.INV(RAND(), 'Lifestyle Strategy'!$F$2, 'Lifestyle Strategy'!$G$2) ),IF(AV13 = "", "",0)) -> 12527.189 | AP13: =I13 * ( 'Lifestyle Strategy'!$B$3 + ('Lifestyle Strategy'!$C$3 - 'Lifestyle Strategy'!$B$3) * _xlfn.BETA.INV(RAND(), 'Lifestyle Strategy'!$F$3, 'Lifestyle Strategy'!$G$3) ) * IF(MOD(B13,5)=0, 1 + 'Lifestyle Strategy'!$M$4, 1 + 0.025) -> 7143.0299 | AQ13: =I13 * ( 'Lifestyle Strategy'!$B$4 + ('Lifestyle Strategy'!$C$4 - 'Lifestyle Strategy'!$B$4) * _xlfn.BETA.INV(RAND(), 'Lifestyle Strategy'!$F$4, 'Lifestyle Strategy'!$G$4) ) * IF(MOD(B13,5)=0, 1 + 'Lifestyle Strategy'!$M$4, 1 + 0.025) -> 3780.9441 | AR13: =I13 * ( 'Lifestyle Strategy'!$B$5 + ('Lifestyle Strategy'!$C$5 - 'Lifestyle Strategy'!$B$5) * _xlfn.BETA.INV(RAND(), 'Lifestyle Strategy'!$F$5, 'Lifestyle Strategy'!$G$5) ) * IF(MOD(B13,5)=0, 1 + 'Lifestyle Strategy'!$M$4, 1 + 0.025) -> 2710.2138 | AS13: =I13 * ( 'Lifestyle Strategy'!$B$6 + ('Lifestyle Strategy'!$C$6 - 'Lifestyle Strategy'!$B$6) * _xlfn.BETA.INV(RAND(), 'Lifestyle Strategy'!$F$6, 'Lifestyle Strategy'!$G$6) ) * IF(MOD(B13,5)=0, 1 + 'Lifestyle Strategy'!$M$4, 1 + 0.025) -> 3129.2604 | AT13: =I13 * ( 'Lifestyle Strategy'!$B$7 + ('Lifestyle Strategy'!$C$7 - 'Lifestyle Strategy'!$B$7) * _xlfn.BETA.INV(RAND(), 'Lifestyle Strategy'!$F$7, 'Lifestyle Strategy'!$G$7) ) * IF(MOD(B13,5)=0, 1 + 'Lifestyle Strategy'!$M$4, 1 + 0.025) -> 6621.749 | AU13: =I13 * ( 'Lifestyle Strategy'!$B$8 + ('Lifestyle Strategy'!$C$8 - 'Lifestyle Strategy'!$B$8) * _xlfn.BETA.INV(RAND(), 'Lifestyle Strategy'!$F$8, 'Lifestyle Strategy'!$G$8) ) * IF(MOD(B13,5)=0, 1 + 'Lifestyle Strategy'!$M$4, 1 + 0.025) -> 2029.8467 | AV13: =IF('Lifestyle Strategy'!$B$14 = "Yes", IF(AND(B13>='Lifestyle Strategy'!$B$15, B13<'Lifestyle Strategy'!$B$16), 'Lifestyle Strategy'!$B$25, IF(B13>='Lifestyle Strategy'!$B$16, "", 0) ), 0 ) -> 0 | AW13: =IF('Lifestyle Strategy'!$Q$4="No", 0, IF(AND(B13>='Lifestyle Strategy'!$Q$5, B13<'Lifestyle Strategy'!$Q$6), 'Lifestyle Strategy'!$Q$8 * (1.025^(B13-'Lifestyle Strategy'!$Q$5)) * (1.12^INT((B13-'Lifestyle Strategy'!$Q$5)/5)), 0 ) ) -> 0 | AX13: =IF(AO13 = "",0,AO13)+AP13+AQ13+AR13+AS13+AT13+AU13+AW13+IF(AV13 = "",0,AV13) -> 37942.233 | AY13: =IF(B13='Lifestyle Strategy'!$Q$10, MIN(AN13, 'Lifestyle Strategy'!$Q$11), 0) -> 0 | AZ13: =IF(B13='Lifestyle Strategy'!$Q$10, 'Lifestyle Strategy'!$Q$11, 0) -> 0 | BA13: =IF(B13='Lifestyle Strategy'!$Q$10, MAX(AZ13 - AY13, 0), 0) -> 0 | BB13: =U13+Y13+AC13+AJ13+AN13-AY13 -> 3530.9072 | BC13: =TEXT(BB13/1000000, "[$$-en-US]0.00") & "M" -> $0.00M
B14: 1 | C14: 31 | D14: =IF(B14<>$B$5,D13*(1+_xlfn.NORM.INV(RAND(),$B$3,$B$4)),D13*(1+_xlfn.NORM.INV(RAND(),$B$3,$B$4))+D13*(1+_xlfn.NORM.INV(RAND(),$B$3,$B$4))) -> 72057.192 | E14: =D14-D13 -> 2057.1917 | F14: =E14/D13 -> 0.029388454 | G14: ='Tax rate cal'!C11 -> 13643.17 | H14: =$B$6*D14 -> 1203.3551 | I14: =D14-G14-H14 -> 57210.667 | J14: =MIN($E$2 + INT(B14/$E$3)*$E$4, $E$5) -> 0.03 | K14: 0.03 | L14: =IF(O14 = 0,0,'Lifestyle Strategy'!$Q$9) -> 0 | M14: =I14*J14 -> 1716.32 | N14: =I14*K14 -> 1716.32 | O14: =IF(AND('Lifestyle Strategy'!$Q$2="Yes", B14 >='Lifestyle Strategy'!$Q$3), I14 * 'Lifestyle Strategy'!$Q$9, 0 ) -> 0 | P14: =IF(B14<10,0,IF(MOD(B14, $E$6) = 0, $E$7, 0)) -> 0 | Q14: =M14+N14+O14+P14 -> 3432.64 | R14: =IF(B14<=5, Q14*'Fund Allocation Strategy'!$B$2, IF(B14<=10, Q14*'Fund Allocation Strategy'!$B$3, IF(B14<=15, Q14*'Fund Allocation Strategy'!$B$4, IF(B14<=20, Q14*'Fund Allocation Strategy'!$B$5, IF(B14<=25, Q14*'Fund Allocation Strategy'!$B$6, IF(B14<=30, Q14*'Fund Allocation Strategy'!$B$7, Q14*'Fund Allocation Strategy'!$B$8)))))) -> 171.632 | S14: =_xlfn.NORM.INV(RAND(),'Fund Allocation Strategy'!$B$11,'Fund Allocation Strategy'!$C$11) -> 0.03690931 | T14: =U13*S14+(R14*S14*0.5) -> 9.4398332 | U14: =U13+R14+T14 -> 351.01334 | V14: =IF(B14<=5, Q14*'Fund Allocation Strategy'!$C$2, IF(B14<=10, Q14*'Fund Allocation Strategy'!$C$3, IF(B14<=15, Q14*'Fund Allocation Strategy'!$C$4, IF(B14<=20, Q14*'Fund Allocation Strategy'!$C$5, IF(B14<=25, Q14*'Fund Allocation Strategy'!$C$6, IF(B14<=30, Q14*'Fund Allocation Strategy'!$C$7, Q14*'Fund Allocation Strategy'!$C$8)))))) -> 171.632 | W14: =_xlfn.NORM.INV(RAND(),'Fund Allocation Strategy'!$B$12,'Fund Allocation Strategy'!$C$12) -> 0.07018111 | X14: =Y13*W14 + (V14*W14*0.5) -> 18.144137 | Y14: =Y13+V14+X14 -> 362.4932 | Z14: =IF(B14<=5, Q14*'Fund Allocation Strategy'!$D$2, IF(B14<=10, Q14*'Fund Allocation Strategy'!$D$3, IF(B14<=15, Q14*'Fund Allocation Strategy'!$D$4, IF(B14<=20, Q14*'Fund Allocation Strategy'!$D$5, IF(B14<=25, Q14*'Fund Allocation Strategy'!$D$6, IF(B14<=30, Q14*'Fund Allocation Strategy'!$D$7, Q14*'Fund Allocation Strategy'!$D$8)))))) -> 1544.688 | AA14: =_xlfn.NORM.INV(RAND(),'Fund Allocation Strategy'!$B$13,'Fund Allocation Strategy'!$C$13) -> 0.10439445 | AB14: =AC13*AA14+(Z14*AA14*0.5) -> 245.36337 | AC14: =AC13+Z14+AB14 -> 3368.0562 | AD14: =IF(B14<=5, Q14*'Fund Allocation Strategy'!$E$2, IF(B14<=10, Q14*'Fund Allocation Strategy'!$E$3, IF(B14<=15, Q14*'Fund Allocation Strategy'!$E$4, IF(B14<=20, Q14*'Fund Allocation Strategy'!$E$5, IF(B14<=25, Q14*'Fund Allocation Strategy'!$E$6, IF(B14<=30, Q14*'Fund Allocation Strategy'!$E$7, Q14*'Fund Allocation Strategy'!$E$8)))))) -> 1029.792 | AE14: =_xlfn.NORM.INV(RAND(), 'Fund Allocation Strategy'!$B$14, 'Fund Allocation Strategy'!$C$14) + _xlfn.NORM.INV(RAND(), 'Fund Allocation Strategy'!$D$14,'Fund Allocation Strategy'!$E$14) -> 0.17614828 | AF14: =AM13*AE14+(AD14*AE14*0.5) -> 277.31435 | AG14: =IF(B14<=5, Q14*'Fund Allocation Strategy'!$F$2, IF(B14<=10, Q14*'Fund Allocation Strategy'!$F$3, IF(B14<=15, Q14*'Fund Allocation Strategy'!$F$4, IF(B14<=20, Q14*'Fund Allocation Strategy'!$F$5, IF(B14<=25, Q14*'Fund Allocation Strategy'!$F$6, IF(B14<=30, Q14*'Fund Allocation Strategy'!$F$7, Q14*'Fund Allocation Strategy'!$F$8)))))) -> 514.896 | AH14: =_xlfn.NORM.INV(RAND(),'Fund Allocation Strategy'!$B$15,'Fund Allocation Strategy'!$C$15) -> 0.19820668 | AI14: =AI13*AH14+(AG14*AH14*0.5) -> 61.002079 | AJ14: =AJ13+AG14+AI14 -> 1126.7146 | AK14: =IF(AM14<50000,0, AM14*0.015) -> 0 | AL14: =IF(AM14<50000,0,0.015) -> 0 | AM14: =AM13+AD14+AF14 -> 2366.5337 | AN14: =AM14-AK14 -> 2366.5337 | AO14: =IF(AV14 = 0, I14 * ( 'Lifestyle Strategy'!$B$2 + ('Lifestyle Strategy'!$C$2 - 'Lifestyle Strategy'!$B$2) * _xlfn.BETA.INV(RAND(), 'Lifestyle Strategy'!$F$2, 'Lifestyle Strategy'!$G$2) ),IF(AV14 = "", "",0)) -> 0 | AP14: =I14 * ( 'Lifestyle Strategy'!$B$3 + ('Lifestyle Strategy'!$C$3 - 'Lifestyle Strategy'!$B$3) * _xlfn.BETA.INV(RAND(), 'Lifestyle Strategy'!$F$3, 'Lifestyle Strategy'!$G$3) ) * IF(MOD(B14,5)=0, 1 + 'Lifestyle Strategy'!$M$4, 1 + 0.025) -> 7770.0435 | AQ14: =I14 * ( 'Lifestyle Strategy'!$B$4 + ('Lifestyle Strategy'!$C$4 - 'Lifestyle Strategy'!$B$4) * _xlfn.BETA.INV(RAND(), 'Lifestyle Strategy'!$F$4, 'Lifestyle Strategy'!$G$4) ) * IF(MOD(B14,5)=0, 1 + 'Lifestyle Strategy'!$M$4, 1 + 0.025) -> 5217.8035 | AR14: =I14 * ( 'Lifestyle Strategy'!$B$5 + ('Lifestyle Strategy'!$C$5 - 'Lifestyle Strategy'!$B$5) * _xlfn.BETA.INV(RAND(), 'Lifestyle Strategy'!$F$5, 'Lifestyle Strategy'!$G$5) ) * IF(MOD(B14,5)=0, 1 + 'Lifestyle Strategy'!$M$4, 1 + 0.025) -> 3034.2146 | AS14: =I14 * ( 'Lifestyle Strategy'!$B$6 + ('Lifestyle Strategy'!$C$6 - 'Lifestyle Strategy'!$B$6) * _xlfn.BETA.INV(RAND(), 'Lifestyle Strategy'!$F$6, 'Lifestyle Strategy'!$G$6) ) * IF(MOD(B14,5)=0, 1 + 'Lifestyle Strategy'!$M$4, 1 + 0.025) -> 2726.7948 | AT14: =I14 * ( 'Lifestyle Strategy'!$B$7 + ('Lifestyle Strategy'!$C$7 - 'Lifestyle Strategy'!$B$7) * _xlfn.BETA.INV(RAND(), 'Lifestyle Strategy'!$F$7, 'Lifestyle Strategy'!$G$7) ) * IF(MOD(B14,5)=0, 1 + 'Lifestyle Strategy'!$M$4, 1 + 0.025) -> 6270.7471 | AU14: =I14 * ( 'Lifestyle Strategy'!$B$8 + ('Lifestyle Strategy'!$C$8 - 'Lifestyle Strategy'!$B$8) * _xlfn.BETA.INV(RAND(), 'Lifestyle Strategy'!$F$8, 'Lifestyle Strategy'!$G$8) ) * IF(MOD(B14,5)=0, 1 + 'Lifestyle Strategy'!$M$4, 1 + 0.025) -> 3330.5888 | AV14: =IF('Lifestyle Strategy'!$B$14 = "Yes", IF(AND(B14>='Lifestyle Strategy'!$B$15, B14<'Lifestyle Strategy'!$B$16), 'Lifestyle Strategy'!$B$25, IF(B14>='Lifestyle Strategy'!$B$16, "", 0) ), 0 ) -> 17163.2 | AW14: =IF('Lifestyle Strategy'!$Q$4="No", 0, IF(AND(B14>='Lifestyle Strategy'!$Q$5, B14<'Lifestyle Strategy'!$Q$6), 'Lifestyle Strategy'!$Q$8 * (1.025^(B14-'Lifestyle Strategy'!$Q$5)) * (1.12^INT((B14-'Lifestyle Strategy'!$Q$5)/5)), 0 ) ) -> 0 | AX14: =IF(AO14 = "",0,AO14)+AP14+AQ14+AR14+AS14+AT14+AU14+AW14+IF(AV14 = "",0,AV14) -> 45513.392 | AY14: =IF(B14='Lifestyle Strategy'!$Q$10, MIN(AN14, 'Lifestyle Strategy'!$Q$11), 0) -> 0 | AZ14: =IF(B14='Lifestyle Strategy'!$Q$10, 'Lifestyle Strategy'!$Q$11, 0) -> 0 | BA14: =IF(B14='Lifestyle Strategy'!$Q$10, MAX(AZ14 - AY14, 0), 0) -> 0 | BB14: =U14+Y14+AC14+AJ14+AN14-AY14 -> 7574.811 | BC14: =TEXT(BB14/1000000, "[$$-en-US]0.00") & "M" -> $0.01M
B15: 2 | C15: 32 | D15: =IF(B15<>$B$5,D14*(1+_xlfn.NORM.INV(RAND(),$B$3,$B$4)),D14*(1+_xlfn.NORM.INV(RAND(),$B$3,$B$4))+D14*(1+_xlfn.NORM.INV(RAND(),$B$3,$B$4))) -> 73552.962 | E15: =D15-D14 -> 1495.7702 | F15: =E15/D14 -> 0.020758097 | G15: ='Tax rate cal'!C12 -> 14091.901 | H15: =$B$6*D15 -> 1228.3345 | I15: =D15-G15-H15 -> 58232.726 | J15: =MIN($E$2 + INT(B15/$E$3)*$E$4, $E$5) -> 0.04 | K15: 0.03 | L15: =IF(O15 = 0,0,'Lifestyle Strategy'!$Q$9) -> 0 | M15: =I15*J15 -> 2329.3091 | N15: =I15*K15 -> 1746.9818 | O15: =IF(AND('Lifestyle Strategy'!$Q$2="Yes", B15 >='Lifestyle Strategy'!$Q$3), I15 * 'Lifestyle Strategy'!$Q$9, 0 ) -> 0 | P15: =IF(B15<10,0,IF(MOD(B15, $E$6) = 0, $E$7, 0)) -> 0 | Q15: =M15+N15+O15+P15 -> 4076.2908 | R15: =IF(B15<=5, Q15*'Fund Allocation Strategy'!$B$2, IF(B15<=10, Q15*'Fund Allocation Strategy'!$B$3, IF(B15<=15, Q15*'Fund Allocation Strategy'!$B$4, IF(B15<=20, Q15*'Fund Allocation Strategy'!$B$5, IF(B15<=25, Q15*'Fund Allocation Strategy'!$B$6, IF(B15<=30, Q15*'Fund Allocation Strategy'!$B$7, Q15*'Fund Allocation Strategy'!$B$8)))))) -> 203.81454 | S15: =_xlfn.NORM.INV(RAND(),'Fund Allocation Strategy'!$B$11,'Fund Allocation Strategy'!$C$11) -> 0.036604432 | T15: =U14*S15+(R15*S15*0.5) -> 16.578902 | U15: =U14+R15+T15 -> 571.40679 | V15: =IF(B15<=5, Q15*'Fund Allocation Strategy'!$C$2, IF(B15<=10, Q15*'Fund Allocation Strategy'!$C$3, IF(B15<=15, Q15*'Fund Allocation Strategy'!$C$4, IF(B15<=20, Q15*'Fund Allocation Strategy'!$C$5, IF(B15<=25, Q15*'Fund Allocation Strategy'!$C$6, IF(B15<=30, Q15*'Fund Allocation Strategy'!$C$7, Q15*'Fund Allocation Strategy'!$C$8)))))) -> 203.81454 | W15: =_xlfn.NORM.INV(RAND(),'Fund Allocation Strategy'!$B$12,'Fund Allocation Strategy'!$C$12) -> 0.068860126 | X15: =Y14*W15 + (V15*W15*0.5) -> 31.978675 | Y15: =Y14+V15+X15 -> 598.28642 | Z15: =IF(B15<=5, Q15*'Fund Allocation Strategy'!$D$2, IF(B15<=10, Q15*'Fund Allocation Strategy'!$D$3, IF(B15<=15, Q15*'Fund Allocation Strategy'!$D$4, IF(B15<=20, Q15*'Fund Allocation Strategy'!$D$5, IF(B15<=25, Q15*'Fund Allocation Strategy'!$D$6, IF(B15<=30, Q15*'Fund Allocation Strategy'!$D$7, Q15*'Fund Allocation Strategy'!$D$8)))))) -> 1834.3309 | AA15: =_xlfn.NORM.INV(RAND(),'Fund Allocation Strategy'!$B$13,'Fund Allocation Strategy'!$C$13) -> 0.10158051 | AB15: =AC14*AA15+(Z15*AA15*0.5) -> 435.29502 | AC15: =AC14+Z15+AB15 -> 5637.6821 | AD15: =IF(B15<=5, Q15*'Fund Allocation Strategy'!$E$2, IF(B15<=10, Q15*'Fund Allocation Strategy'!$E$3, IF(B15<=15, Q15*'Fund Allocation Strategy'!$E$4, IF(B15<=20, Q15*'Fund Allocation Strategy'!$E$5, IF(B15<=25, Q15*'Fund Allocation Strategy'!$E$6, IF(B15<=30, Q15*'Fund Allocation Strategy'!$E$7, Q15*'Fund Allocation Strategy'!$E$8)))))) -> 1222.8873 | AE15: =_xlfn.NORM.INV(RAND(), 'Fund Allocation Strategy'!$B$14, 'Fund Allocation Strategy'!$C$14) + _xlfn.NORM.INV(RAND(), 'Fund Allocation Strategy'!$D$14,'Fund Allocation Strategy'!$E$14) -> 0.019662552 | AF15: =AM14*AE15+(AD15*AE15*0.5) -> 58.554633 | AG15: =IF(B15<=5, Q15*'Fund Allocation Strategy'!$F$2, IF(B15<=10, Q15*'Fund Allocation Strategy'!$F$3, IF(B15<=15, Q15*'Fund Allocation Strategy'!$F$4, IF(B15<=20, Q15*'Fund Allocation Strategy'!$F$5, IF(B15<=25, Q15*'Fund Allocation Strategy'!$F$6, IF(B15<=30, Q15*'Fund Allocation Strategy'!$F$7, Q15*'Fund Allocation Strategy'!$F$8)))))) -> 611.44363 | AH15: =_xlfn.NORM.INV(RAND(),'Fund Allocation Strategy'!$B$15,'Fund Allocation Strategy'!$C$15) -> 0.21323489 | AI15: =AI14*AH15+(AG15*AH15*0.5) -> 78.198329 | AJ15: =AJ14+AG15+AI15 -> 1816.3566 | AK15: =IF(AM15<50000,0, AM15*0.015) -> 0 | AL15: =IF(AM15<50000,0,0.015) -> 0 | AM15: =AM14+AD15+AF15 -> 3647.9756 | AN15: =AM15-AK15 -> 3647.9756 | AO15: =IF(AV15 = 0, I15 * ( 'Lifestyle Strategy'!$B$2 + ('Lifestyle Strategy'!$C$2 - 'Lifestyle Strategy'!$B$2) * _xlfn.BETA.INV(RAND(), 'Lifestyle Strategy'!$F$2, 'Lifestyle Strategy'!$G$2) ),IF(AV15 = "", "",0)) -> 0 | AP15: =I15 * ( 'Lifestyle Strategy'!$B$3 + ('Lifestyle Strategy'!$C$3 - 'Lifestyle Strategy'!$B$3) * _xlfn.BETA.INV(RAND(), 'Lifestyle Strategy'!$F$3, 'Lifestyle Strategy'!$G$3) ) * IF(MOD(B15,5)=0, 1 + 'Lifestyle Strategy'!$M$4, 1 + 0.025) -> 7966.7114 | AQ15: =I15 * ( 'Lifestyle Strategy'!$B$4 + ('Lifestyle Strategy'!$C$4 - 'Lifestyle Strategy'!$B$4) * _xlfn.BETA.INV(RAND(), 'Lifestyle Strategy'!$F$4, 'Lifestyle Strategy'!$G$4) ) * IF(MOD(B15,5)=0, 1 + 'Lifestyle Strategy'!$M$4, 1 + 0.025) -> 5865.7163 | AR15: =I15 * ( 'Lifestyle Strategy'!$B$5 + ('Lifestyle Strategy'!$C$5 - 'Lifestyle Strategy'!$B$5) * _xlfn.BETA.INV(RAND(), 'Lifestyle Strategy'!$F$5, 'Lifestyle Strategy'!$G$5) ) * IF(MOD(B15,5)=0, 1 + 'Lifestyle Strategy'!$M$4, 1 + 0.025) -> 3109.2717 | AS15: =I15 * ( 'Lifestyle Strategy'!$B$6 + ('Lifestyle Strategy'!$C$6 - 'Lifestyle Strategy'!$B$6) * _xlfn.BETA.INV(RAND(), 'Lifestyle Strategy'!$F$6, 'Lifestyle Strategy'!$G$6) ) * IF(MOD(B15,5)=0, 1 + 'Lifestyle Strategy'!$M$4, 1 + 0.025) -> 2980.6443 | AT15: =I15 * ( 'Lifestyle Strategy'!$B$7 + ('Lifestyle Strategy'!$C$7 - 'Lifestyle Strategy'!$B$7) * _xlfn.BETA.INV(RAND(), 'Lifestyle Strategy'!$F$7, 'Lifestyle Strategy'!$G$7) ) * IF(MOD(B15,5)=0, 1 + 'Lifestyle Strategy'!$M$4, 1 + 0.025) -> 5773.6762 | AU15: =I15 * ( 'Lifestyle Strategy'!$B$8 + ('Lifestyle Strategy'!$C$8 - 'Lifestyle Strategy'!$B$8) * _xlfn.BETA.INV(RAND(), 'Lifestyle Strategy'!$F$8, 'Lifestyle Strategy'!$G$8) ) * IF(MOD(B15,5)=0, 1 + 'Lifestyle Strategy'!$M$4, 1 + 0.025) -> 2248.2523 | AV15: =IF('Lifestyle Strategy'!$B$14 = "Yes", IF(AND(B15>='Lifestyle Strategy'!$B$15, B15<'Lifestyle Strategy'!$B$16), 'Lifestyle Strategy'!$B$25, IF(B15>='Lifestyle Strategy'!$B$16, "", 0) ), 0 ) -> 17163.2 | AW15: =IF('Lifestyle Strategy'!$Q$4="No", 0, IF(AND(B15>='Lifestyle Strategy'!$Q$5, B15<'Lifestyle Strategy'!$Q$6), 'Lifestyle Strategy'!$Q$8 * (1.025^(B15-'Lifestyle Strategy'!$Q$5)) * (1.12^INT((B15-'Lifestyle Strategy'!$Q$5)/5)), 0 ) ) -> 0 | AX15: =IF(AO15 = "",0,AO15)+AP15+AQ15+AR15+AS15+AT15+AU15+AW15+IF(AV15 = "",0,AV15) -> 45107.472 | AY15: =IF(B15='Lifestyle Strategy'!$Q$10, MIN(AN15, 'Lifestyle Strategy'!$Q$11), 0) -> 0 | AZ15: =IF(B15='Lifestyle Strategy'!$Q$10, 'Lifestyle Strategy'!$Q$11, 0) -> 0 | BA15: =IF(B15='Lifestyle Strategy'!$Q$10, MAX(AZ15 - AY15, 0), 0) -> 0 | BB15: =U15+Y15+AC15+AJ15+AN15-AY15 -> 12271.707 | BC15: =TEXT(BB15/1000000, "[$$-en-US]0.00") & "M" -> $0.01M | BQ15: Index | BR15: Post-Retirement Year | BS15: Age | BT15: Target Lifestyle Spending | BU15: Target Spending % of Corpus | BV15: Govt Support (NZ Super) | BW15: Withdrawal from Fund | BX15: Withdrawal % of Corpus | BY15: Annual Return Rate (%) | BZ15: Growth (NZD) | CA15: Remaining Corpus | CB15: Expected Corpus
B16: 3 | C16: 33 | D16: =IF(B16<>$B$5,D15*(1+_xlfn.NORM.INV(RAND(),$B$3,$B$4)),D15*(1+_xlfn.NORM.INV(RAND(),$B$3,$B$4))+D15*(1+_xlfn.NORM.INV(RAND(),$B$3,$B$4))) -> 76356.463 | E16: =D16-D15 -> 2803.5011 | F16: =E16/D15 -> 0.038115408 | G16: ='Tax rate cal'!C13 -> 14932.951 | H16: =$B$6*D16 -> 1275.1529 | I16: =D16-G16-H16 -> 60148.359 | J16: =MIN($E$2 + INT(B16/$E$3)*$E$4, $E$5) -> 0.04 | K16: 0.03 | L16: =IF(O16 = 0,0,'Lifestyle Strategy'!$Q$9) -> 0 | M16: =I16*J16 -> 2405.9343 | N16: =I16*K16 -> 1804.4508 | O16: =IF(AND('Lifestyle Strategy'!$Q$2="Yes", B16 >='Lifestyle Strategy'!$Q$3), I16 * 'Lifestyle Strategy'!$Q$9, 0 ) -> 0 | P16: =IF(B16<10,0,IF(MOD(B16, $E$6) = 0, $E$7, 0)) -> 0 | Q16: =M16+N16+O16+P16 -> 4210.3851 | R16: =IF(B16<=5, Q16*'Fund Allocation Strategy'!$B$2, IF(B16<=10, Q16*'Fund Allocation Strategy'!$B$3, IF(B16<=15, Q16*'Fund Allocation Strategy'!$B$4, IF(B16<=20, Q16*'Fund Allocation Strategy'!$B$5, IF(B16<=25, Q16*'Fund Allocation Strategy'!$B$6, IF(B16<=30, Q16*'Fund Allocation Strategy'!$B$7, Q16*'Fund Allocation Strategy'!$B$8)))))) -> 210.51926 | S16: =_xlfn.NORM.INV(RAND(),'Fund Allocation Strategy'!$B$11,'Fund Allocation Strategy'!$C$11) -> 0.037194842 | T16: =U15*S16+(R16*S16*0.5) -> 25.1685 | U16: =U15+R16+T16 -> 807.09454 | V16: =IF(B16<=5, Q16*'Fund Allocation Strategy'!$C$2, IF(B16<=10, Q16*'Fund Allocation Strategy'!$C$3, IF(B16<=15, Q16*'Fund Allocation Strategy'!$C$4, IF(B16<=20, Q16*'Fund Allocation Strategy'!$C$5, IF(B16<=25, Q16*'Fund Allocation Strategy'!$C$6, IF(B16<=30, Q16*'Fund Allocation Strategy'!$C$7, Q16*'Fund Allocation Strategy'!$C$8)))))) -> 210.51926 | W16: =_xlfn.NORM.INV(RAND(),'Fund Allocation Strategy'!$B$12,'Fund Allocation Strategy'!$C$12) -> 0.071244218 | X16: =Y15*W16 + (V16*W16*0.5) -> 50.123588 | Y16: =Y15+V16+X16 -> 858.92926 | Z16: =IF(B16<=5, Q16*'Fund Allocation Strategy'!$D$2, IF(B16<=10, Q16*'Fund Allocation Strategy'!$D$3, IF(B16<=15, Q16*'Fund Allocation Strategy'!$D$4, IF(B16<=20, Q16*'Fund Allocation Strategy'!$D$5, IF(B16<=25, Q16*'Fund Allocation Strategy'!$D$6, IF(B16<=30, Q16*'Fund Allocation Strategy'!$D$7, Q16*'Fund Allocation Strategy'!$D$8)))))) -> 1894.6733 | AA16: =_xlfn.NORM.INV(RAND(),'Fund Allocation Strategy'!$B$13,'Fund Allocation Strategy'!$C$13) -> 0.1043149 | AB16: =AC15*AA16+(Z16*AA16*0.5) -> 686.91554 | AC16: =AC15+Z16+AB16 -> 8219.2709 | AD16: =IF(B16<=5, Q16*'Fund Allocation Strategy'!$E$2, IF(B16<=10, Q16*'Fund Allocation Strategy'!$E$3, IF(B16<=15, Q16*'Fund Allocation Strategy'!$E$4, IF(B16<=20, Q16*'Fund Allocation Strategy'!$E$5, IF(B16<=25, Q16*'Fund Allocation Strategy'!$E$6, IF(B16<=30, Q16*'Fund Allocation Strategy'!$E$7, Q16*'Fund Allocation Strategy'!$E$8)))))) -> 1263.1155 | AE16: =_xlfn.NORM.INV(RAND(), 'Fund Allocation Strategy'!$B$14, 'Fund Allocation Strategy'!$C$14) + _xlfn.NORM.INV(RAND(), 'Fund Allocation Strategy'!$D$14,'Fund Allocation Strategy'!$E$14) -> 0.2836789 | AF16: =AM15*AE16+(AD16*AE16*0.5) -> 1214.0133 | AG16: =IF(B16<=5, Q16*'Fund Allocation Strategy'!$F$2, IF(B16<=10, Q16*'Fund Allocation Strategy'!$F$3, IF(B16<=15, Q16*'Fund Allocation Strategy'!$F$4, IF(B16<=20, Q16*'Fund Allocation Strategy'!$F$5, IF(B16<=25, Q16*'Fund Allocation Strategy'!$F$6, IF(B16<=30, Q16*'Fund Allocation Strategy'!$F$7, Q16*'Fund Allocation Strategy'!$F$8)))))) -> 631.55777 | AH16: =_xlfn.NORM.INV(RAND(),'Fund Allocation Strategy'!$B$15,'Fund Allocation Strategy'!$C$15) -> 0.20019019 | AI16: =AI15*AH16+(AG16*AH16*0.5) -> 78.870375 | AJ16: =AJ15+AG16+AI16 -> 2526.7847 | AK16: =IF(AM16<50000,0, AM16*0.015) -> 0 | AL16: =IF(AM16<50000,0,0.015) -> 0 | AM16: =AM15+AD16+AF16 -> 6125.1044 | AN16: =AM16-AK16 -> 6125.1044 | AO16: =IF(AV16 = 0, I16 * ( 'Lifestyle Strategy'!$B$2 + ('Lifestyle Strategy'!$C$2 - 'Lifestyle Strategy'!$B$2) * _xlfn.BETA.INV(RAND(), 'Lifestyle Strategy'!$F$2, 'Lifestyle Strategy'!$G$2) ),IF(AV16 = "", "",0)) -> 0 | AP16: =I16 * ( 'Lifestyle Strategy'!$B$3 + ('Lifestyle Strategy'!$C$3 - 'Lifestyle Strategy'!$B$3) * _xlfn.BETA.INV(RAND(), 'Lifestyle Strategy'!$F$3, 'Lifestyle Strategy'!$G$3) ) * IF(MOD(B16,5)=0, 1 + 'Lifestyle Strategy'!$M$4, 1 + 0.025) -> 8051.6206 | AQ16: =I16 * ( 'Lifestyle Strategy'!$B$4 + ('Lifestyle Strategy'!$C$4 - 'Lifestyle Strategy'!$B$4) * _xlfn.BETA.INV(RAND(), 'Lifestyle Strategy'!$F$4, 'Lifestyle Strategy'!$G$4) ) * IF(MOD(B16,5)=0, 1 + 'Lifestyle Strategy'!$M$4, 1 + 0.025) -> 3877.3029 | AR16: =I16 * ( 'Lifestyle Strategy'!$B$5 + ('Lifestyle Strategy'!$C$5 - 'Lifestyle Strategy'!$B$5) * _xlfn.BETA.INV(RAND(), 'Lifestyle Strategy'!$F$5, 'Lifestyle Strategy'!$G$5) ) * IF(MOD(B16,5)=0, 1 + 'Lifestyle Strategy'!$M$4, 1 + 0.025) -> 3318.1232 | AS16: =I16 * ( 'Lifestyle Strategy'!$B$6 + ('Lifestyle Strategy'!$C$6 - 'Lifestyle Strategy'!$B$6) * _xlfn.BETA.INV(RAND(), 'Lifestyle Strategy'!$F$6, 'Lifestyle Strategy'!$G$6) ) * IF(MOD(B16,5)=0, 1 + 'Lifestyle Strategy'!$M$4, 1 + 0.025) -> 3217.9259 | AT16: =I16 * ( 'Lifestyle Strategy'!$B$7 + ('Lifestyle Strategy'!$C$7 - 'Lifestyle Strategy'!$B$7) * _xlfn.BETA.INV(RAND(), 'Lifestyle Strategy'!$F$7, 'Lifestyle Strategy'!$G$7) ) * IF(MOD(B16,5)=0, 1 + 'Lifestyle Strategy'!$M$4, 1 + 0.025) -> 6811.4114 | AU16: =I16 * ( 'Lifestyle Strategy'!$B$8 + ('Lifestyle Strategy'!$C$8 - 'Lifestyle Strategy'!$B$8) * _xlfn.BETA.INV(RAND(), 'Lifestyle Strategy'!$F$8, 'Lifestyle Strategy'!$G$8) ) * IF(MOD(B16,5)=0, 1 + 'Lifestyle Strategy'!$M$4, 1 + 0.025) -> 3051.9537 | AV16: =IF('Lifestyle Strategy'!$B$14 = "Yes", IF(AND(B16>='Lifestyle Strategy'!$B$15, B16<'Lifestyle Strategy'!$B$16), 'Lifestyle Strategy'!$B$25, IF(B16>='Lifestyle Strategy'!$B$16, "", 0) ), 0 ) -> 17163.2 | AW16: =IF('Lifestyle Strategy'!$Q$4="No", 0, IF(AND(B16>='Lifestyle Strategy'!$Q$5, B16<'Lifestyle Strategy'!$Q$6), 'Lifestyle Strategy'!$Q$8 * (1.025^(B16-'Lifestyle Strategy'!$Q$5)) * (1.12^INT((B16-'Lifestyle Strategy'!$Q$5)/5)), 0 ) ) -> 0 | AX16: =IF(AO16 = "",0,AO16)+AP16+AQ16+AR16+AS16+AT16+AU16+AW16+IF(AV16 = "",0,AV16) -> 45491.538 | AY16: =IF(B16='Lifestyle Strategy'!$Q$10, MIN(AN16, 'Lifestyle Strategy'!$Q$11), 0) -> 0 | AZ16: =IF(B16='Lifestyle Strategy'!$Q$10, 'Lifestyle Strategy'!$Q$11, 0) -> 0 | BA16: =IF(B16='Lifestyle Strategy'!$Q$10, MAX(AZ16 - AY16, 0), 0) -> 0 | BB16: =U16+Y16+AC16+AJ16+AN16-AY16 -> 18537.184 | BC16: =TEXT(BB16/1000000, "[$$-en-US]0.00") & "M" -> $0.02M | BR16: 1 | BS16: 66 | BT16: =AX48 -> 143809.59 | BU16: =BT16/CA16 -> 0.029713728 | BV16: ='Lifestyle Strategy'!$M$22*(1+'Lifestyle Strategy'!$M$16)^('Lifestyle Strategy'!$M$23 + BR16-1) -> 54583.719 | BW16: =BT16-BV16 -> 89225.872 | BX16: =BW16/CA16 -> 0.018435719 | BY16: =IFERROR(_xlfn.NORM.INV(RAND(),'Lifestyle Strategy'!$M$27,'Lifestyle Strategy'!$M$28),0) -> 0.02602631 | BZ16: ='Lifestyle Strategy'!$M$26*BY16 -> 125031.21 | CA16: =('Pre-Retirement_cal'!$BB$48 + BZ16)-BW16 -> 4839836.7 | CB16: =IF('Post-Retirement_Cal'!$K16<0, ABS('Post-Retirement_Cal'!$K16),0) -> 0
B17: 4 | C17: 34 | D17: =IF(B17<>$B$5,D16*(1+_xlfn.NORM.INV(RAND(),$B$3,$B$4)),D16*(1+_xlfn.NORM.INV(RAND(),$B$3,$B$4))+D16*(1+_xlfn.NORM.INV(RAND(),$B$3,$B$4))) -> 79363.04 | E17: =D17-D16 -> 3006.5765 | F17: =E17/D16 -> 0.039375534 | G17: ='Tax rate cal'!C14 -> 15834.924 | H17: =$B$6*D17 -> 1325.3628 | I17: =D17-G17-H17 -> 62202.752 | J17: =MIN($E$2 + INT(B17/$E$3)*$E$4, $E$5) -> 0.05 | K17: 0.03 | L17: =IF(O17 = 0,0,'Lifestyle Strategy'!$Q$9) -> 0 | M17: =I17*J17 -> 3110.1376 | N17: =I17*K17 -> 1866.0826 | O17: =IF(AND('Lifestyle Strategy'!$Q$2="Yes", B17 >='Lifestyle Strategy'!$Q$3), I17 * 'Lifestyle Strategy'!$Q$9, 0 ) -> 0 | P17: =IF(B17<10,0,IF(MOD(B17, $E$6) = 0, $E$7, 0)) -> 0 | Q17: =M17+N17+O17+P17 -> 4976.2202 | R17: =IF(B17<=5, Q17*'Fund Allocation Strategy'!$B$2, IF(B17<=10, Q17*'Fund Allocation Strategy'!$B$3, IF(B17<=15, Q17*'Fund Allocation Strategy'!$B$4, IF(B17<=20, Q17*'Fund Allocation Strategy'!$B$5, IF(B17<=25, Q17*'Fund Allocation Strategy'!$B$6, IF(B17<=30, Q17*'Fund Allocation Strategy'!$B$7, Q17*'Fund Allocation Strategy'!$B$8)))))) -> 248.81101 | S17: =_xlfn.NORM.INV(RAND(),'Fund Allocation Strategy'!$B$11,'Fund Allocation Strategy'!$C$11) -> 0.037570372 | T17: =U16*S17+(R17*S17*0.5) -> 34.996803 | U17: =U16+R17+T17 -> 1090.9024 | V17: =IF(B17<=5, Q17*'Fund Allocation Strategy'!$C$2, IF(B17<=10, Q17*'Fund Allocation Strategy'!$C$3, IF(B17<=15, Q17*'Fund Allocation Strategy'!$C$4, IF(B17<=20, Q17*'Fund Allocation Strategy'!$C$5, IF(B17<=25, Q17*'Fund Allocation Strategy'!$C$6, IF(B17<=30, Q17*'Fund Allocation Strategy'!$C$7, Q17*'Fund Allocation Strategy'!$C$8)))))) -> 248.81101 | W17: =_xlfn.NORM.INV(RAND(),'Fund Allocation Strategy'!$B$12,'Fund Allocation Strategy'!$C$12) -> 0.070351282 | X17: =Y16*W17 + (V17*W17*0.5) -> 69.178861 | Y17: =Y16+V17+X17 -> 1176.9191 | Z17: =IF(B17<=5, Q17*'Fund Allocation Strategy'!$D$2, IF(B17<=10, Q17*'Fund Allocation Strategy'!$D$3, IF(B17<=15, Q17*'Fund Allocation Strategy'!$D$4, IF(B17<=20, Q17*'Fund Allocation Strategy'!$D$5, IF(B17<=25, Q17*'Fund Allocation Strategy'!$D$6, IF(B17<=30, Q17*'Fund Allocation Strategy'!$D$7, Q17*'Fund Allocation Strategy'!$D$8)))))) -> 2239.2991 | AA17: =_xlfn.NORM.INV(RAND(),'Fund Allocation Strategy'!$B$13,'Fund Allocation Strategy'!$C$13) -> 0.10462586 | AB17: =AC16*AA17+(Z17*AA17*0.5) -> 977.09262 | AC17: =AC16+Z17+AB17 -> 11435.663 | AD17: =IF(B17<=5, Q17*'Fund Allocation Strategy'!$E$2, IF(B17<=10, Q17*'Fund Allocation Strategy'!$E$3, IF(B17<=15, Q17*'Fund Allocation Strategy'!$E$4, IF(B17<=20, Q17*'Fund Allocation Strategy'!$E$5, IF(B17<=25, Q17*'Fund Allocation Strategy'!$E$6, IF(B17<=30, Q17*'Fund Allocation Strategy'!$E$7, Q17*'Fund Allocation Strategy'!$E$8)))))) -> 1492.8661 | AE17: =_xlfn.NORM.INV(RAND(), 'Fund Allocation Strategy'!$B$14, 'Fund Allocation Strategy'!$C$14) + _xlfn.NORM.INV(RAND(), 'Fund Allocation Strategy'!$D$14,'Fund Allocation Strategy'!$E$14) -> 0.5750956 | AF17: =AM16*AE17+(AD17*AE17*0.5) -> 3951.7909 | AG17: =IF(B17<=5, Q17*'Fund Allocation Strategy'!$F$2, IF(B17<=10, Q17*'Fund Allocation Strategy'!$F$3, IF(B17<=15, Q17*'Fund Allocation Strategy'!$F$4, IF(B17<=20, Q17*'Fund Allocation Strategy'!$F$5, IF(B17<=25, Q17*'Fund Allocation Strategy'!$F$6, IF(B17<=30, Q17*'Fund Allocation Strategy'!$F$7, Q17*'Fund Allocation Strategy'!$F$8)))))) -> 746.43303 | AH17: =_xlfn.NORM.INV(RAND(),'Fund Allocation Strategy'!$B$15,'Fund Allocation Strategy'!$C$15) -> 0.21176197 | AI17: =AI16*AH17+(AG17*AH17*0.5) -> 95.734809 | AJ17: =AJ16+AG17+AI17 -> 3368.9526 | AK17: =IF(AM17<50000,0, AM17*0.015) -> 0 | AL17: =IF(AM17<50000,0,0.015) -> 0 | AM17: =AM16+AD17+AF17 -> 11569.761 | AN17: =AM17-AK17 -> 11569.761 | AO17: =IF(AV17 = 0, I17 * ( 'Lifestyle Strategy'!$B$2 + ('Lifestyle Strategy'!$C$2 - 'Lifestyle Strategy'!$B$2) * _xlfn.BETA.INV(RAND(), 'Lifestyle Strategy'!$F$2, 'Lifestyle Strategy'!$G$2) ),IF(AV17 = "", "",0)) -> 0 | AP17: =I17 * ( 'Lifestyle Strategy'!$B$3 + ('Lifestyle Strategy'!$C$3 - 'Lifestyle Strategy'!$B$3) * _xlfn.BETA.INV(RAND(), 'Lifestyle Strategy'!$F$3, 'Lifestyle Strategy'!$G$3) ) * IF(MOD(B17,5)=0, 1 + 'Lifestyle Strategy'!$M$4, 1 + 0.025) -> 7483.0972 | AQ17: =I17 * ( 'Lifestyle Strategy'!$B$4 + ('Lifestyle Strategy'!$C$4 - 'Lifestyle Strategy'!$B$4) * _xlfn.BETA.INV(RAND(), 'Lifestyle Strategy'!$F$4, 'Lifestyle Strategy'!$G$4) ) * IF(MOD(B17,5)=0, 1 + 'Lifestyle Strategy'!$M$4, 1 + 0.025) -> 5212.5531 | AR17: =I17 * ( 'Lifestyle Strategy'!$B$5 + ('Lifestyle Strategy'!$C$5 - 'Lifestyle Strategy'!$B$5) * _xlfn.BETA.INV(RAND(), 'Lifestyle Strategy'!$F$5, 'Lifestyle Strategy'!$G$5) ) * IF(MOD(B17,5)=0, 1 + 'Lifestyle Strategy'!$M$4, 1 + 0.025) -> 3216.3509 | AS17: =I17 * ( 'Lifestyle Strategy'!$B$6 + ('Lifestyle Strategy'!$C$6 - 'Lifestyle Strategy'!$B$6) * _xlfn.BETA.INV(RAND(), 'Lifestyle Strategy'!$F$6, 'Lifestyle Strategy'!$G$6) ) * IF(MOD(B17,5)=0, 1 + 'Lifestyle Strategy'!$M$4, 1 + 0.025) -> 3290.1145 | AT17: =I17 * ( 'Lifestyle Strategy'!$B$7 + ('Lifestyle Strategy'!$C$7 - 'Lifestyle Strategy'!$B$7) * _xlfn.BETA.INV(RAND(), 'Lifestyle Strategy'!$F$7, 'Lifestyle Strategy'!$G$7) ) * IF(MOD(B17,5)=0, 1 + 'Lifestyle Strategy'!$M$4, 1 + 0.025) -> 6613.1781 | AU17: =I17 * ( 'Lifestyle Strategy'!$B$8 + ('Lifestyle Strategy'!$C$8 - 'Lifestyle Strategy'!$B$8) * _xlfn.BETA.INV(RAND(), 'Lifestyle Strategy'!$F$8, 'Lifestyle Strategy'!$G$8) ) * IF(MOD(B17,5)=0, 1 + 'Lifestyle Strategy'!$M$4, 1 + 0.025) -> 2995.5482 | AV17: =IF('Lifestyle Strategy'!$B$14 = "Yes", IF(AND(B17>='Lifestyle Strategy'!$B$15, B17<'Lifestyle Strategy'!$B$16), 'Lifestyle Strategy'!$B$25, IF(B17>='Lifestyle Strategy'!$B$16, "", 0) ), 0 ) -> 17163.2 | AW17: =IF('Lifestyle Strategy'!$Q$4="No", 0, IF(AND(B17>='Lifestyle Strategy'!$Q$5, B17<'Lifestyle Strategy'!$Q$6), 'Lifestyle Strategy'!$Q$8 * (1.025^(B17-'Lifestyle Strategy'!$Q$5)) * (1.12^INT((B17-'Lifestyle Strategy'!$Q$5)/5)), 0 ) ) -> 0 | AX17: =IF(AO17 = "",0,AO17)+AP17+AQ17+AR17+AS17+AT17+AU17+AW17+IF(AV17 = "",0,AV17) -> 45974.042 | AY17: =IF(B17='Lifestyle Strategy'!$Q$10, MIN(AN17, 'Lifestyle Strategy'!$Q$11), 0) -> 0 | AZ17: =IF(B17='Lifestyle Strategy'!$Q$10, 'Lifestyle Strategy'!$Q$11, 0) -> 0 | BA17: =IF(B17='Lifestyle Strategy'!$Q$10, MAX(AZ17 - AY17, 0), 0) -> 0 | BB17: =U17+Y17+AC17+AJ17+AN17-AY17 -> 28642.198 | BC17: =TEXT(BB17/1000000, "[$$-en-US]0.00") & "M" -> $0.03M | BR17: 2 | BS17: 67 | BT17: =IF(BS17<'Lifestyle Strategy'!$M$14, 0, 'Lifestyle Strategy'!$M$15 * (1 + 'Lifestyle Strategy'!$M$16)^(BS17-'Lifestyle Strategy'!$M$14) * (1 + IF(RAND() < (0.08 - 0.06) / (0.1 - 0.06), 0.06 + SQRT(RAND() * (0.08 - 0.06) * (0.1 - 0.06)), 0.1 - SQRT((1 - RAND()) * (0.1 - 0.08) * (0.1 - 0.06)) ))^INT((BS17-'Lifestyle Strategy'!$M$14)/5) ) -> 147404.83 | BU17: =BT17/CA17 -> 0.029954804 | BV17: ='Lifestyle Strategy'!$M$22*(1+'Lifestyle Strategy'!$M$16)^('Lifestyle Strategy'!$M$23 + BR17-1) -> 55948.312 | BW17: =BT17-BV17 -> 91456.519 | BX17: =BW17/CA17 -> 0.018585294 | BY17: =IFERROR(_xlfn.NORM.INV(RAND(),'Lifestyle Strategy'!$M$27,'Lifestyle Strategy'!$M$28),0) -> 0.035647396 | BZ17: =CA16*BY17 -> 172527.58 | CA17: =(CA16+BZ17)-BW17 -> 4920907.8 | CB17: =IF('Post-Retirement_Cal'!$K17<0, ABS('Post-Retirement_Cal'!$K17),0) -> 0
B18: 5 | C18: 35 | D18: =IF(B18<>$B$5,D17*(1+_xlfn.NORM.INV(RAND(),$B$3,$B$4)),D17*(1+_xlfn.NORM.INV(RAND(),$B$3,$B$4))+D17*(1+_xlfn.NORM.INV(RAND(),$B$3,$B$4))) -> 82334.238 | E18: =D18-D17 -> 2971.1982 | F18: =E18/D17 -> 0.03743806 | G18: ='Tax rate cal'!C15 -> 16794.736 | H18: =$B$6*D18 -> 1374.9818 | I18: =D18-G18-H18 -> 64164.52 | J18: =MIN($E$2 + INT(B18/$E$3)*$E$4, $E$5) -> 0.05 | K18: 0.03 | L18: =IF(O18 = 0,0,'Lifestyle Strategy'!$Q$9) -> 0 | M18: =I18*J18 -> 3208.226 | N18: =I18*K18 -> 1924.9356 | O18: =IF(AND('Lifestyle Strategy'!$Q$2="Yes", B18 >='Lifestyle Strategy'!$Q$3), I18 * 'Lifestyle Strategy'!$Q$9, 0 ) -> 0 | P18: =IF(B18<10,0,IF(MOD(B18, $E$6) = 0, $E$7, 0)) -> 0 | Q18: =M18+N18+O18+P18 -> 5133.1616 | R18: =IF(B18<=5, Q18*'Fund Allocation Strategy'!$B$2, IF(B18<=10, Q18*'Fund Allocation Strategy'!$B$3, IF(B18<=15, Q18*'Fund Allocation Strategy'!$B$4, IF(B18<=20, Q18*'Fund Allocation Strategy'!$B$5, IF(B18<=25, Q18*'Fund Allocation Strategy'!$B$6, IF(B18<=30, Q18*'Fund Allocation Strategy'!$B$7, Q18*'Fund Allocation Strategy'!$B$8)))))) -> 256.65808 | S18: =_xlfn.NORM.INV(RAND(),'Fund Allocation Strategy'!$B$11,'Fund Allocation Strategy'!$C$11) -> 0.037355341 | T18: =U17*S18+(R18*S18*0.5) -> 45.544805 | U18: =U17+R18+T18 -> 1393.1052 | V18: =IF(B18<=5, Q18*'Fund Allocation Strategy'!$C$2, IF(B18<=10, Q18*'Fund Allocation Strategy'!$C$3, IF(B18<=15, Q18*'Fund Allocation Strategy'!$C$4, IF(B18<=20, Q18*'Fund Allocation Strategy'!$C$5, IF(B18<=25, Q18*'Fund Allocation Strategy'!$C$6, IF(B18<=30, Q18*'Fund Allocation Strategy'!$C$7, Q18*'Fund Allocation Strategy'!$C$8)))))) -> 256.65808 | W18: =_xlfn.NORM.INV(RAND(),'Fund Allocation Strategy'!$B$12,'Fund Allocation Strategy'!$C$12) -> 0.070688407 | X18: =Y17*W18 + (V18*W18*0.5) -> 92.265914 | Y18: =Y17+V18+X18 -> 1525.8431 | Z18: =IF(B18<=5, Q18*'Fund Allocation Strategy'!$D$2, IF(B18<=10, Q18*'Fund Allocation Strategy'!$D$3, IF(B18<=15, Q18*'Fund Allocation Strategy'!$D$4, IF(B18<=20, Q18*'Fund Allocation Strategy'!$D$5, IF(B18<=25, Q18*'Fund Allocation Strategy'!$D$6, IF(B18<=30, Q18*'Fund Allocation Strategy'!$D$7, Q18*'Fund Allocation Strategy'!$D$8)))))) -> 2309.9227 | AA18: =_xlfn.NORM.INV(RAND(),'Fund Allocation Strategy'!$B$13,'Fund Allocation Strategy'!$C$13) -> 0.10638208 | AB18: =AC17*AA18+(Z18*AA18*0.5) -> 1339.4167 | AC18: =AC17+Z18+AB18 -> 15085.002 | AD18: =IF(B18<=5, Q18*'Fund Allocation Strategy'!$E$2, IF(B18<=10, Q18*'Fund Allocation Strategy'!$E$3, IF(B18<=15, Q18*'Fund Allocation Strategy'!$E$4, IF(B18<=20, Q18*'Fund Allocation Strategy'!$E$5, IF(B18<=25, Q18*'Fund Allocation Strategy'!$E$6, IF(B18<=30, Q18*'Fund Allocation Strategy'!$E$7, Q18*'Fund Allocation Strategy'!$E$8)))))) -> 1539.9485 | AE18: =_xlfn.NORM.INV(RAND(), 'Fund Allocation Strategy'!$B$14, 'Fund Allocation Strategy'!$C$14) + _xlfn.NORM.INV(RAND(), 'Fund Allocation Strategy'!$D$14,'Fund Allocation Strategy'!$E$14) -> 0.11889284 | AF18: =AM17*AE18+(AD18*AE18*0.5) -> 1467.1062 | AG18: =IF(B18<=5, Q18*'Fund Allocation Strategy'!$F$2, IF(B18<=10, Q18*'Fund Allocation Strategy'!$F$3, IF(B18<=15, Q18*'Fund Allocation Strategy'!$F$4, IF(B18<=20, Q18*'Fund Allocation Strategy'!$F$5, IF(B18<=25, Q18*'Fund Allocation Strategy'!$F$6, IF(B18<=30, Q18*'Fund Allocation Strategy'!$F$7, Q18*'Fund Allocation Strategy'!$F$8)))))) -> 769.97424 | AH18: =_xlfn.NORM.INV(RAND(),'Fund Allocation Strategy'!$B$15,'Fund Allocation Strategy'!$C$15) -> 0.21020493 | AI18: =AI17*AH18+(AG18*AH18*0.5) -> 101.05012 | AJ18: =AJ17+AG18+AI18 -> 4239.9769 | AK18: =IF(AM18<50000,0, AM18*0.015) -> 0 | AL18: =IF(AM18<50000,0,0.015) -> 0 | AM18: =AM17+AD18+AF18 -> 14576.816 | AN18: =AM18-AK18 -> 14576.816 | AO18: =IF(AV18 = 0, I18 * ( 'Lifestyle Strategy'!$B$2 + ('Lifestyle Strategy'!$C$2 - 'Lifestyle Strategy'!$B$2) * _xlfn.BETA.INV(RAND(), 'Lifestyle Strategy'!$F$2, 'Lifestyle Strategy'!$G$2) ),IF(AV18 = "", "",0)) -> 0 | AP18: =I18 * ( 'Lifestyle Strategy'!$B$3 + ('Lifestyle Strategy'!$C$3 - 'Lifestyle Strategy'!$B$3) * _xlfn.BETA.INV(RAND(), 'Lifestyle Strategy'!$F$3, 'Lifestyle Strategy'!$G$3) ) * IF(MOD(B18,5)=0, 1 + 'Lifestyle Strategy'!$M$4, 1 + 0.025) -> 9644.806 | AQ18: =I18 * ( 'Lifestyle Strategy'!$B$4 + ('Lifestyle Strategy'!$C$4 - 'Lifestyle Strategy'!$B$4) * _xlfn.BETA.INV(RAND(), 'Lifestyle Strategy'!$F$4, 'Lifestyle Strategy'!$G$4) ) * IF(MOD(B18,5)=0, 1 + 'Lifestyle Strategy'!$M$4, 1 + 0.025) -> 6398.9283 | AR18: =I18 * ( 'Lifestyle Strategy'!$B$5 + ('Lifestyle Strategy'!$C$5 - 'Lifestyle Strategy'!$B$5) * _xlfn.BETA.INV(RAND(), 'Lifestyle Strategy'!$F$5, 'Lifestyle Strategy'!$G$5) ) * IF(MOD(B18,5)=0, 1 + 'Lifestyle Strategy'!$M$4, 1 + 0.025) -> 3473.3699 | AS18: =I18 * ( 'Lifestyle Strategy'!$B$6 + ('Lifestyle Strategy'!$C$6 - 'Lifestyle Strategy'!$B$6) * _xlfn.BETA.INV(RAND(), 'Lifestyle Strategy'!$F$6, 'Lifestyle Strategy'!$G$6) ) * IF(MOD(B18,5)=0, 1 + 'Lifestyle Strategy'!$M$4, 1 + 0.025) -> 3688.1278 | AT18: =I18 * ( 'Lifestyle Strategy'!$B$7 + ('Lifestyle Strategy'!$C$7 - 'Lifestyle Strategy'!$B$7) * _xlfn.BETA.INV(RAND(), 'Lifestyle Strategy'!$F$7, 'Lifestyle Strategy'!$G$7) ) * IF(MOD(B18,5)=0, 1 + 'Lifestyle Strategy'!$M$4, 1 + 0.025) -> 7893.4044 | AU18: =I18 * ( 'Lifestyle Strategy'!$B$8 + ('Lifestyle Strategy'!$C$8 - 'Lifestyle Strategy'!$B$8) * _xlfn.BETA.INV(RAND(), 'Lifestyle Strategy'!$F$8, 'Lifestyle Strategy'!$G$8) ) * IF(MOD(B18,5)=0, 1 + 'Lifestyle Strategy'!$M$4, 1 + 0.025) -> 2385.8151 | AV18: =IF('Lifestyle Strategy'!$B$14 = "Yes", IF(AND(B18>='Lifestyle Strategy'!$B$15, B18<'Lifestyle Strategy'!$B$16), 'Lifestyle Strategy'!$B$25, IF(B18>='Lifestyle Strategy'!$B$16, "", 0) ), 0 ) -> 17163.2 | AW18: =IF('Lifestyle Strategy'!$Q$4="No", 0, IF(AND(B18>='Lifestyle Strategy'!$Q$5, B18<'Lifestyle Strategy'!$Q$6), 'Lifestyle Strategy'!$Q$8 * (1.025^(B18-'Lifestyle Strategy'!$Q$5)) * (1.12^INT((B18-'Lifestyle Strategy'!$Q$5)/5)), 0 ) ) -> 0 | AX18: =IF(AO18 = "",0,AO18)+AP18+AQ18+AR18+AS18+AT18+AU18+AW18+IF(AV18 = "",0,AV18) -> 50647.651 | AY18: =IF(B18='Lifestyle Strategy'!$Q$10, MIN(AN18, 'Lifestyle Strategy'!$Q$11), 0) -> 0 | AZ18: =IF(B18='Lifestyle Strategy'!$Q$10, 'Lifestyle Strategy'!$Q$11, 0) -> 0 | BA18: =IF(B18='Lifestyle Strategy'!$Q$10, MAX(AZ18 - AY18, 0), 0) -> 0 | BB18: =U18+Y18+AC18+AJ18+AN18-AY18 -> 36820.743 | BC18: =TEXT(BB18/1000000, "[$$-en-US]0.00") & "M" -> $0.04M | BR18: 3 | BS18: 68 | BT18: =IF(BS18<'Lifestyle Strategy'!$M$14, 0, 'Lifestyle Strategy'!$M$15 * (1 + 'Lifestyle Strategy'!$M$16)^(BS18-'Lifestyle Strategy'!$M$14) * (1 + IF(RAND() < (0.08 - 0.06) / (0.1 - 0.06), 0.06 + SQRT(RAND() * (0.08 - 0.06) * (0.1 - 0.06)), 0.1 - SQRT((1 - RAND()) * (0.1 - 0.08) * (0.1 - 0.06)) ))^INT((BS18-'Lifestyle Strategy'!$M$14)/5) ) -> 151089.95 | BU18: =BT18/CA18 -> 0.029952948 | BV18: ='Lifestyle Strategy'!$M$22*(1+'Lifestyle Strategy'!$M$16)^('Lifestyle Strategy'!$M$23 + BR18-1) -> 57347.02 | BW18: =BT18-BV18 -> 93742.932 | BX18: =BW18/CA18 -> 0.018584142 | BY18: =IFERROR(_xlfn.NORM.INV(RAND(),'Lifestyle Strategy'!$M$27,'Lifestyle Strategy'!$M$28),0) -> 0.044113463 | BZ18: =CA17*BY18 -> 217078.28 | CA18: =(CA17+BZ18)-BW18 -> 5044243.2 | CB18: =IF('Post-Retirement_Cal'!$K18<0, ABS('Post-Retirement_Cal'!$K18),0) -> 0
B19: 6 | C19: 36 | D19: =IF(B19<>$B$5,D18*(1+_xlfn.NORM.INV(RAND(),$B$3,$B$4)),D18*(1+_xlfn.NORM.INV(RAND(),$B$3,$B$4))+D18*(1+_xlfn.NORM.INV(RAND(),$B$3,$B$4))) -> 85475.278 | E19: =D19-D18 -> 3141.0404 | F19: =E19/D18 -> 0.038149869 | G19: ='Tax rate cal'!C16 -> 17831.279 | H19: =$B$6*D19 -> 1427.4371 | I19: =D19-G19-H19 -> 66216.562 | J19: =MIN($E$2 + INT(B19/$E$3)*$E$4, $E$5) -> 0.06 | K19: 0.03 | L19: =IF(O19 = 0,0,'Lifestyle Strategy'!$Q$9) -> 0 | M19: =I19*J19 -> 3972.9937 | N19: =I19*K19 -> 1986.4969 | O19: =IF(AND('Lifestyle Strategy'!$Q$2="Yes", B19 >='Lifestyle Strategy'!$Q$3), I19 * 'Lifestyle Strategy'!$Q$9, 0 ) -> 0 | P19: =IF(B19<10,0,IF(MOD(B19, $E$6) = 0, $E$7, 0)) -> 0 | Q19: =M19+N19+O19+P19 -> 5959.4906 | R19: =IF(B19<=5, Q19*'Fund Allocation Strategy'!$B$2, IF(B19<=10, Q19*'Fund Allocation Strategy'!$B$3, IF(B19<=15, Q19*'Fund Allocation Strategy'!$B$4, IF(B19<=20, Q19*'Fund Allocation Strategy'!$B$5, IF(B19<=25, Q19*'Fund Allocation Strategy'!$B$6, IF(B19<=30, Q19*'Fund Allocation Strategy'!$B$7, Q19*'Fund Allocation Strategy'!$B$8)))))) -> 595.94906 | S19: =_xlfn.NORM.INV(RAND(),'Fund Allocation Strategy'!$B$11,'Fund Allocation Strategy'!$C$11) -> 0.036709626 | T19: =U18*S19+(R19*S19*0.5) -> 62.078905 | U19: =U18+R19+T19 -> 2051.1332 | V19: =IF(B19<=5, Q19*'Fund Allocation Strategy'!$C$2, IF(B19<=10, Q19*'Fund Allocation Strategy'!$C$3, IF(B19<=15, Q19*'Fund Allocation Strategy'!$C$4, IF(B19<=20, Q19*'Fund Allocation Strategy'!$C$5, IF(B19<=25, Q19*'Fund Allocation Strategy'!$C$6, IF(B19<=30, Q19*'Fund Allocation Strategy'!$C$7, Q19*'Fund Allocation Strategy'!$C$8)))))) -> 744.93632 | W19: =_xlfn.NORM.INV(RAND(),'Fund Allocation Strategy'!$B$12,'Fund Allocation Strategy'!$C$12) -> 0.070584419 | X19: =Y18*W19 + (V19*W19*0.5) -> 133.9912 | Y19: =Y18+V19+X19 -> 2404.7706 | Z19: =IF(B19<=5, Q19*'Fund Allocation Strategy'!$D$2, IF(B19<=10, Q19*'Fund Allocation Strategy'!$D$3, IF(B19<=15, Q19*'Fund Allocation Strategy'!$D$4, IF(B19<=20, Q19*'Fund Allocation Strategy'!$D$5, IF(B19<=25, Q19*'Fund Allocation Strategy'!$D$6, IF(B19<=30, Q19*'Fund Allocation Strategy'!$D$7, Q19*'Fund Allocation Strategy'!$D$8)))))) -> 2383.7962 | AA19: =_xlfn.NORM.INV(RAND(),'Fund Allocation Strategy'!$B$13,'Fund Allocation Strategy'!$C$13) -> 0.1054413 | AB19: =AC18*AA19+(Z19*AA19*0.5) -> 1716.2575 | AC19: =AC18+Z19+AB19 -> 19185.056 | AD19: =IF(B19<=5, Q19*'Fund Allocation Strategy'!$E$2, IF(B19<=10, Q19*'Fund Allocation Strategy'!$E$3, IF(B19<=15, Q19*'Fund Allocation Strategy'!$E$4, IF(B19<=20, Q19*'Fund Allocation Strategy'!$E$5, IF(B19<=25, Q19*'Fund Allocation Strategy'!$E$6, IF(B19<=30, Q19*'Fund Allocation Strategy'!$E$7, Q19*'Fund Allocation Strategy'!$E$8)))))) -> 1489.8726 | AE19: =_xlfn.NORM.INV(RAND(), 'Fund Allocation Strategy'!$B$14, 'Fund Allocation Strategy'!$C$14) + _xlfn.NORM.INV(RAND(), 'Fund Allocation Strategy'!$D$14,'Fund Allocation Strategy'!$E$14) -> 0.18814095 | AF19: =AM18*AE19+(AD19*AE19*0.5) -> 2882.649 | AG19: =IF(B19<=5, Q19*'Fund Allocation Strategy'!$F$2, IF(B19<=10, Q19*'Fund Allocation Strategy'!$F$3, IF(B19<=15, Q19*'Fund Allocation Strategy'!$F$4, IF(B19<=20, Q19*'Fund Allocation Strategy'!$F$5, IF(B19<=25, Q19*'Fund Allocation Strategy'!$F$6, IF(B19<=30, Q19*'Fund Allocation Strategy'!$F$7, Q19*'Fund Allocation Strategy'!$F$8)))))) -> 744.93632 | AH19: =_xlfn.NORM.INV(RAND(),'Fund Allocation Strategy'!$B$15,'Fund Allocation Strategy'!$C$15) -> 0.2112588 | AI19: =AI18*AH19+(AG19*AH19*0.5) -> 100.0349 | AJ19: =AJ18+AG19+AI19 -> 5084.9481 | AK19: =IF(AM19<50000,0, AM19*0.015) -> 0 | AL19: =IF(AM19<50000,0,0.015) -> 0 | AM19: =AM18+AD19+AF19 -> 18949.338 | AN19: =AM19-AK19 -> 18949.338 | AO19: =IF(AV19 = 0, I19 * ( 'Lifestyle Strategy'!$B$2 + ('Lifestyle Strategy'!$C$2 - 'Lifestyle Strategy'!$B$2) * _xlfn.BETA.INV(RAND(), 'Lifestyle Strategy'!$F$2, 'Lifestyle Strategy'!$G$2) ),IF(AV19 = "", "",0)) -> 0 | AP19: =I19 * ( 'Lifestyle Strategy'!$B$3 + ('Lifestyle Strategy'!$C$3 - 'Lifestyle Strategy'!$B$3) * _xlfn.BETA.INV(RAND(), 'Lifestyle Strategy'!$F$3, 'Lifestyle Strategy'!$G$3) ) * IF(MOD(B19,5)=0, 1 + 'Lifestyle Strategy'!$M$4, 1 + 0.025) -> 7325.2228 | AQ19: =I19 * ( 'Lifestyle Strategy'!$B$4 + ('Lifestyle Strategy'!$C$4 - 'Lifestyle Strategy'!$B$4) * _xlfn.BETA.INV(RAND(), 'Lifestyle Strategy'!$F$4, 'Lifestyle Strategy'!$G$4) ) * IF(MOD(B19,5)=0, 1 + 'Lifestyle Strategy'!$M$4, 1 + 0.025) -> 4971.6273 | AR19: =I19 * ( 'Lifestyle Strategy'!$B$5 + ('Lifestyle Strategy'!$C$5 - 'Lifestyle Strategy'!$B$5) * _xlfn.BETA.INV(RAND(), 'Lifestyle Strategy'!$F$5, 'Lifestyle Strategy'!$G$5) ) * IF(MOD(B19,5)=0, 1 + 'Lifestyle Strategy'!$M$4, 1 + 0.025) -> 3492.0943 | AS19: =I19 * ( 'Lifestyle Strategy'!$B$6 + ('Lifestyle Strategy'!$C$6 - 'Lifestyle Strategy'!$B$6) * _xlfn.BETA.INV(RAND(), 'Lifestyle Strategy'!$F$6, 'Lifestyle Strategy'!$G$6) ) * IF(MOD(B19,5)=0, 1 + 'Lifestyle Strategy'!$M$4, 1 + 0.025) -> 3233.5167 | AT19: =I19 * ( 'Lifestyle Strategy'!$B$7 + ('Lifestyle Strategy'!$C$7 - 'Lifestyle Strategy'!$B$7) * _xlfn.BETA.INV(RAND(), 'Lifestyle Strategy'!$F$7, 'Lifestyle Strategy'!$G$7) ) * IF(MOD(B19,5)=0, 1 + 'Lifestyle Strategy'!$M$4, 1 + 0.025) -> 6096.6183 | AU19: =I19 * ( 'Lifestyle Strategy'!$B$8 + ('Lifestyle Strategy'!$C$8 - 'Lifestyle Strategy'!$B$8) * _xlfn.BETA.INV(RAND(), 'Lifestyle Strategy'!$F$8, 'Lifestyle Strategy'!$G$8) ) * IF(MOD(B19,5)=0, 1 + 'Lifestyle Strategy'!$M$4, 1 + 0.025) -> 4230.3433 | AV19: =IF('Lifestyle Strategy'!$B$14 = "Yes", IF(AND(B19>='Lifestyle Strategy'!$B$15, B19<'Lifestyle Strategy'!$B$16), 'Lifestyle Strategy'!$B$25, IF(B19>='Lifestyle Strategy'!$B$16, "", 0) ), 0 ) -> 17163.2 | AW19: =IF('Lifestyle Strategy'!$Q$4="No", 0, IF(AND(B19>='Lifestyle Strategy'!$Q$5, B19<'Lifestyle Strategy'!$Q$6), 'Lifestyle Strategy'!$Q$8 * (1.025^(B19-'Lifestyle Strategy'!$Q$5)) * (1.12^INT((B19-'Lifestyle Strategy'!$Q$5)/5)), 0 ) ) -> 0 | AX19: =IF(AO19 = "",0,AO19)+AP19+AQ19+AR19+AS19+AT19+AU19+AW19+IF(AV19 = "",0,AV19) -> 46512.623 | AY19: =IF(B19='Lifestyle Strategy'!$Q$10, MIN(AN19, 'Lifestyle Strategy'!$Q$11), 0) -> 0 | AZ19: =IF(B19='Lifestyle Strategy'!$Q$10, 'Lifestyle Strategy'!$Q$11, 0) -> 0 | BA19: =IF(B19='Lifestyle Strategy'!$Q$10, MAX(AZ19 - AY19, 0), 0) -> 0 | BB19: =U19+Y19+AC19+AJ19+AN19-AY19 -> 47675.246 | BC19: =TEXT(BB19/1000000, "[$$-en-US]0.00") & "M" -> $0.05M | BR19: 4 | BS19: 69 | BT19: =IF(BS19<'Lifestyle Strategy'!$M$14, 0, 'Lifestyle Strategy'!$M$15 * (1 + 'Lifestyle Strategy'!$M$16)^(BS19-'Lifestyle Strategy'!$M$14) * (1 + IF(RAND() < (0.08 - 0.06) / (0.1 - 0.06), 0.06 + SQRT(RAND() * (0.08 - 0.06) * (0.1 - 0.06)), 0.1 - SQRT((1 - RAND()) * (0.1 - 0.08) * (0.1 - 0.06)) ))^INT((BS19-'Lifestyle Strategy'!$M$14)/5) ) -> 154867.2 | BU19: =BT19/CA19 -> 0.029810999 | BV19: ='Lifestyle Strategy'!$M$22*(1+'Lifestyle Strategy'!$M$16)^('Lifestyle Strategy'!$M$23 + BR19-1) -> 58780.696 | BW19: =BT19-BV19 -> 96086.505 | BX19: =BW19/CA19 -> 0.01849607 | BY19: =IFERROR(_xlfn.NORM.INV(RAND(),'Lifestyle Strategy'!$M$27,'Lifestyle Strategy'!$M$28),0) -> 0.048929427 | BZ19: =CA18*BY19 -> 246811.92 | CA19: =(CA18+BZ19)-BW19 -> 5194968.6 | CB19: =IF('Post-Retirement_Cal'!$K19<0, ABS('Post-Retirement_Cal'!$K19),0) -> 0
B20: 7 | C20: 37 | D20: =IF(B20<>$B$5,D19*(1+_xlfn.NORM.INV(RAND(),$B$3,$B$4)),D19*(1+_xlfn.NORM.INV(RAND(),$B$3,$B$4))+D19*(1+_xlfn.NORM.INV(RAND(),$B$3,$B$4))) -> 89433.648 | E20: =D20-D19 -> 3958.3701 | F20: =E20/D19 -> 0.046310117 | G20: ='Tax rate cal'!C17 -> 19137.541 | H20: =$B$6*D20 -> 1493.5419 | I20: =D20-G20-H20 -> 68802.565 | J20: =MIN($E$2 + INT(B20/$E$3)*$E$4, $E$5) -> 0.06 | K20: 0.03 | L20: =IF(O20 = 0,0,'Lifestyle Strategy'!$Q$9) -> 0 | M20: =I20*J20 -> 4128.1539 | N20: =I20*K20 -> 2064.0769 | O20: =IF(AND('Lifestyle Strategy'!$Q$2="Yes", B20 >='Lifestyle Strategy'!$Q$3), I20 * 'Lifestyle Strategy'!$Q$9, 0 ) -> 0 | P20: =IF(B20<10,0,IF(MOD(B20, $E$6) = 0, $E$7, 0)) -> 0 | Q20: =M20+N20+O20+P20 -> 6192.2308 | R20: =IF(B20<=5, Q20*'Fund Allocation Strategy'!$B$2, IF(B20<=10, Q20*'Fund Allocation Strategy'!$B$3, IF(B20<=15, Q20*'Fund Allocation Strategy'!$B$4, IF(B20<=20, Q20*'Fund Allocation Strategy'!$B$5, IF(B20<=25, Q20*'Fund Allocation Strategy'!$B$6, IF(B20<=30, Q20*'Fund Allocation Strategy'!$B$7, Q20*'Fund Allocation Strategy'!$B$8)))))) -> 619.22308 | S20: =_xlfn.NORM.INV(RAND(),'Fund Allocation Strategy'!$B$11,'Fund Allocation Strategy'!$C$11) -> 0.037891515 | T20: =U19*S20+(R20*S20*0.5) -> 89.452196 | U20: =U19+R20+T20 -> 2759.8085 | V20: =IF(B20<=5, Q20*'Fund Allocation Strategy'!$C$2, IF(B20<=10, Q20*'Fund Allocation Strategy'!$C$3, IF(B20<=15, Q20*'Fund Allocation Strategy'!$C$4, IF(B20<=20, Q20*'Fund Allocation Strategy'!$C$5, IF(B20<=25, Q20*'Fund Allocation Strategy'!$C$6, IF(B20<=30, Q20*'Fund Allocation Strategy'!$C$7, Q20*'Fund Allocation Strategy'!$C$8)))))) -> 774.02886 | W20: =_xlfn.NORM.INV(RAND(),'Fund Allocation Strategy'!$B$12,'Fund Allocation Strategy'!$C$12) -> 0.068615264 | X20: =Y19*W20 + (V20*W20*0.5) -> 191.55907 | Y20: =Y19+V20+X20 -> 3370.3586 | Z20: =IF(B20<=5, Q20*'Fund Allocation Strategy'!$D$2, IF(B20<=10, Q20*'Fund Allocation Strategy'!$D$3, IF(B20<=15, Q20*'Fund Allocation Strategy'!$D$4, IF(B20<=20, Q20*'Fund Allocation Strategy'!$D$5, IF(B20<=25, Q20*'Fund Allocation Strategy'!$D$6, IF(B20<=30, Q20*'Fund Allocation Strategy'!$D$7, Q20*'Fund Allocation Strategy'!$D$8)))))) -> 2476.8923 | AA20: =_xlfn.NORM.INV(RAND(),'Fund Allocation Strategy'!$B$13,'Fund Allocation Strategy'!$C$13) -> 0.10079415 | AB20: =AC19*AA20+(Z20*AA20*0.5) -> 2058.5695 | AC20: =AC19+Z20+AB20 -> 23720.518 | AD20: =IF(B20<=5, Q20*'Fund Allocation Strategy'!$E$2, IF(B20<=10, Q20*'Fund Allocation Strategy'!$E$3, IF(B20<=15, Q20*'Fund Allocation Strategy'!$E$4, IF(B20<=20, Q20*'Fund Allocation Strategy'!$E$5, IF(B20<=25, Q20*'Fund Allocation Strategy'!$E$6, IF(B20<=30, Q20*'Fund Allocation Strategy'!$E$7, Q20*'Fund Allocation Strategy'!$E$8)))))) -> 1548.0577 | AE20: =_xlfn.NORM.INV(RAND(), 'Fund Allocation Strategy'!$B$14, 'Fund Allocation Strategy'!$C$14) + _xlfn.NORM.INV(RAND(), 'Fund Allocation Strategy'!$D$14,'Fund Allocation Strategy'!$E$14) -> 0.031419889 | AF20: =AM19*AE20+(AD20*AE20*0.5) -> 619.70599 | AG20: =IF(B20<=5, Q20*'Fund Allocation Strategy'!$F$2, IF(B20<=10, Q20*'Fund Allocation Strategy'!$F$3, IF(B20<=15, Q20*'Fund Allocation Strategy'!$F$4, IF(B20<=20, Q20*'Fund Allocation Strategy'!$F$5, IF(B20<=25, Q20*'Fund Allocation Strategy'!$F$6, IF(B20<=30, Q20*'Fund Allocation Strategy'!$F$7, Q20*'Fund Allocation Strategy'!$F$8)))))) -> 774.02886 | AH20: =_xlfn.NORM.INV(RAND(),'Fund Allocation Strategy'!$B$15,'Fund Allocation Strategy'!$C$15) -> 0.20247357 | AI20: =AI19*AH20+(AG20*AH20*0.5) -> 98.614616 | AJ20: =AJ19+AG20+AI20 -> 5957.5916 | AK20: =IF(AM20<50000,0, AM20*0.015) -> 0 | AL20: =IF(AM20<50000,0,0.015) -> 0 | AM20: =AM19+AD20+AF20 -> 21117.101 | AN20: =AM20-AK20 -> 21117.101 | AO20: =IF(AV20 = 0, I20 * ( 'Lifestyle Strategy'!$B$2 + ('Lifestyle Strategy'!$C$2 - 'Lifestyle Strategy'!$B$2) * _xlfn.BETA.INV(RAND(), 'Lifestyle Strategy'!$F$2, 'Lifestyle Strategy'!$G$2) ),IF(AV20 = "", "",0)) -> 0 | AP20: =I20 * ( 'Lifestyle Strategy'!$B$3 + ('Lifestyle Strategy'!$C$3 - 'Lifestyle Strategy'!$B$3) * _xlfn.BETA.INV(RAND(), 'Lifestyle Strategy'!$F$3, 'Lifestyle Strategy'!$G$3) ) * IF(MOD(B20,5)=0, 1 + 'Lifestyle Strategy'!$M$4, 1 + 0.025) -> 8863.4337 | AQ20: =I20 * ( 'Lifestyle Strategy'!$B$4 + ('Lifestyle Strategy'!$C$4 - 'Lifestyle Strategy'!$B$4) * _xlfn.BETA.INV(RAND(), 'Lifestyle Strategy'!$F$4, 'Lifestyle Strategy'!$G$4) ) * IF(MOD(B20,5)=0, 1 + 'Lifestyle Strategy'!$M$4, 1 + 0.025) -> 4854.9966 | AR20: =I20 * ( 'Lifestyle Strategy'!$B$5 + ('Lifestyle Strategy'!$C$5 - 'Lifestyle Strategy'!$B$5) * _xlfn.BETA.INV(RAND(), 'Lifestyle Strategy'!$F$5, 'Lifestyle Strategy'!$G$5) ) * IF(MOD(B20,5)=0, 1 + 'Lifestyle Strategy'!$M$4, 1 + 0.025) -> 3472.2914 | AS20: =I20 * ( 'Lifestyle Strategy'!$B$6 + ('Lifestyle Strategy'!$C$6 - 'Lifestyle Strategy'!$B$6) * _xlfn.BETA.INV(RAND(), 'Lifestyle Strategy'!$F$6, 'Lifestyle Strategy'!$G$6) ) * IF(MOD(B20,5)=0, 1 + 'Lifestyle Strategy'!$M$4, 1 + 0.025) -> 3908.8022 | AT20: =I20 * ( 'Lifestyle Strategy'!$B$7 + ('Lifestyle Strategy'!$C$7 - 'Lifestyle Strategy'!$B$7) * _xlfn.BETA.INV(RAND(), 'Lifestyle Strategy'!$F$7, 'Lifestyle Strategy'!$G$7) ) * IF(MOD(B20,5)=0, 1 + 'Lifestyle Strategy'!$M$4, 1 + 0.025) -> 7707.797 | AU20: =I20 * ( 'Lifestyle Strategy'!$B$8 + ('Lifestyle Strategy'!$C$8 - 'Lifestyle Strategy'!$B$8) * _xlfn.BETA.INV(RAND(), 'Lifestyle Strategy'!$F$8, 'Lifestyle Strategy'!$G$8) ) * IF(MOD(B20,5)=0, 1 + 'Lifestyle Strategy'!$M$4, 1 + 0.025) -> 3200.2233 | AV20: =IF('Lifestyle Strategy'!$B$14 = "Yes", IF(AND(B20>='Lifestyle Strategy'!$B$15, B20<'Lifestyle Strategy'!$B$16), 'Lifestyle Strategy'!$B$25, IF(B20>='Lifestyle Strategy'!$B$16, "", 0) ), 0 ) -> 17163.2 | AW20: =IF('Lifestyle Strategy'!$Q$4="No", 0, IF(AND(B20>='Lifestyle Strategy'!$Q$5, B20<'Lifestyle Strategy'!$Q$6), 'Lifestyle Strategy'!$Q$8 * (1.025^(B20-'Lifestyle Strategy'!$Q$5)) * (1.12^INT((B20-'Lifestyle Strategy'!$Q$5)/5)), 0 ) ) -> 0 | AX20: =IF(AO20 = "",0,AO20)+AP20+AQ20+AR20+AS20+AT20+AU20+AW20+IF(AV20 = "",0,AV20) -> 49170.744 | AY20: =IF(B20='Lifestyle Strategy'!$Q$10, MIN(AN20, 'Lifestyle Strategy'!$Q$11), 0) -> 0 | AZ20: =IF(B20='Lifestyle Strategy'!$Q$10, 'Lifestyle Strategy'!$Q$11, 0) -> 0 | BA20: =IF(B20='Lifestyle Strategy'!$Q$10, MAX(AZ20 - AY20, 0), 0) -> 0 | BB20: =U20+Y20+AC20+AJ20+AN20-AY20 -> 56925.378 | BC20: =TEXT(BB20/1000000, "[$$-en-US]0.00") & "M" -> $0.06M | BR20: 5 | BS20: 70 | BT20: =IF(BS20<'Lifestyle Strategy'!$M$14, 0, 'Lifestyle Strategy'!$M$15 * (1 + 'Lifestyle Strategy'!$M$16)^(BS20-'Lifestyle Strategy'!$M$14) * (1 + IF(RAND() < (0.08 - 0.06) / (0.1 - 0.06), 0.06 + SQRT(RAND() * (0.08 - 0.06) * (0.1 - 0.06)), 0.1 - SQRT((1 - RAND()) * (0.1 - 0.08) * (0.1 - 0.06)) ))^INT((BS20-'Lifestyle Strategy'!$M$14)/5) ) -> 158738.88 | BU20: =BT20/CA20 -> 0.030827979 | BV20: ='Lifestyle Strategy'!$M$22*(1+'Lifestyle Strategy'!$M$16)^('Lifestyle Strategy'!$M$23 + BR20-1) -> 60250.213 | BW20: =BT20-BV20 -> 98488.668 | BX20: =BW20/CA20 -> 0.019127051 | BY20: =IFERROR(_xlfn.NORM.INV(RAND(),'Lifestyle Strategy'!$M$27,'Lifestyle Strategy'!$M$28),0) -> 0.010144856 | BZ20: =CA19*BY20 -> 52702.211 | CA20: =(CA19+BZ20)-BW20 -> 5149182.1 | CB20: =IF('Post-Retirement_Cal'!$K20<0, ABS('Post-Retirement_Cal'!$K20),0) -> 0
